Testing module: chatgpt
************* Module chatgpt
generated/code/calculator/3-chain_of_thoughts-zero_shot/iteration_4/chatgpt.py:45:0: C0301: Line too long (105/100) (line-too-long)
generated/code/calculator/3-chain_of_thoughts-zero_shot/iteration_4/chatgpt.py:78:0: C0301: Line too long (133/100) (line-too-long)
generated/code/calculator/3-chain_of_thoughts-zero_shot/iteration_4/chatgpt.py:106:0: C0301: Line too long (125/100) (line-too-long)
generated/code/calculator/3-chain_of_thoughts-zero_shot/iteration_4/chatgpt.py:1:0: C0114: Missing module docstring (missing-module-docstring)
generated/code/calculator/3-chain_of_thoughts-zero_shot/iteration_4/chatgpt.py:31:8: W0621: Redefining name 'result' from outer scope (line 241) (redefined-outer-name)
generated/code/calculator/3-chain_of_thoughts-zero_shot/iteration_4/chatgpt.py:70:20: R1724: Unnecessary "else" after "continue", remove the "else" and de-indent the code inside it (no-else-continue)
generated/code/calculator/3-chain_of_thoughts-zero_shot/iteration_4/chatgpt.py:53:8: R1702: Too many nested blocks (7/5) (too-many-nested-blocks)
generated/code/calculator/3-chain_of_thoughts-zero_shot/iteration_4/chatgpt.py:84:28: W0707: Consider explicitly re-raising using 'except ValueError as exc' and 'raise ValueError(f'Invalid number format: {num_str}') from exc' (raise-missing-from)
generated/code/calculator/3-chain_of_thoughts-zero_shot/iteration_4/chatgpt.py:112:20: W0707: Consider explicitly re-raising using 'except ValueError as exc' and 'raise ValueError(f'Invalid number format: {num_str}') from exc' (raise-missing-from)
generated/code/calculator/3-chain_of_thoughts-zero_shot/iteration_4/chatgpt.py:34:4: R0912: Too many branches (17/12) (too-many-branches)
generated/code/calculator/3-chain_of_thoughts-zero_shot/iteration_4/chatgpt.py:213:20: W0621: Redefining name 'result' from outer scope (line 241) (redefined-outer-name)
generated/code/calculator/3-chain_of_thoughts-zero_shot/iteration_4/chatgpt.py:1:0: R0903: Too few public methods (1/2) (too-few-public-methods)
generated/code/calculator/3-chain_of_thoughts-zero_shot/iteration_4/chatgpt.py:243:15: W0718: Catching too general exception Exception (broad-exception-caught)

------------------------------------------------------------------
Your code has been rated at 9.02/10 (previous run: 8.94/10, +0.08)

